Workbook

Sheet Sayfa1
A1: Plaka | B1: Ekipman_Kodu | C1: Planlama ÜY | D1: Planlama grubu | E1: Masraf yeri | F1: Sorumlu işyeri | G1: Arac_Sinifi_Kodu | H1: Arac_Sinifi_Adi | I1: Marka_Model | J1: Motor_Seri_No | K1: Şaşi No | L1: Ruhsat No
A2: =VLOOKUP(B2,Sayfa2!A:O,15,0) -> 06CBB253 | B2: =Sayfa2!A3 -> BA-090 | C2: =VLOOKUP(B2,Sayfa2!A:G,7,0) -> 1035 | D2: =VLOOKUP(B2,Sayfa2!A:H,8,0) -> 135 | E2: =VLOOKUP(B2,Sayfa2!A:I,9,0) -> 10001035 | F2: =VLOOKUP(B2,Sayfa2!A:J,10,0) -> 1035-01 | G2: =IF(H2="BINEKARAC", 702001, IF(H2="CEKICI", 702002, IF(H2="KAMYON GRP", 702002, IF(H2="SERVISARAC", 702002, IF(H2="KAMYONET", 702011, 702003))))) -> 702001 | H2: =VLOOKUP(B2,Sayfa2!A:K,11,0) -> BINEKARAC | I2: =VLOOKUP(B2,Sayfa2!A:N,13,0) -> OTOMOBİL FIAT EGEA 1.3 MULTIJET | J2: =VLOOKUP(B2,Sayfa2!A:AI,35,0) | K2: =VLOOKUP(Sayfa1!B2,Sayfa2!A:AU,47,0) -> ZFA35600006S14994 | L2: =VLOOKUP(B2,Sayfa2!A:U,21,0) -> FP303298
A3: =VLOOKUP(B3,Sayfa2!A:O,15,0) -> 06EZE162 | B3: =Sayfa2!A4 -> BA-254 | C3: =VLOOKUP(B3,Sayfa2!A:G,7,0) -> 1035 | D3: =VLOOKUP(B3,Sayfa2!A:H,8,0) -> 135 | E3: =VLOOKUP(B3,Sayfa2!A:I,9,0) -> 10001035 | F3: =VLOOKUP(B3,Sayfa2!A:J,10,0) -> 1035-01 | G3: =IF(H3="BINEKARAC", 702001, IF(H3="CEKICI", 702002, IF(H3="KAMYON GRP", 702002, IF(H3="SERVISARAC", 702002, IF(H3="KAMYONET", 702011, 702003))))) -> 702001 | H3: =VLOOKUP(B3,Sayfa2!A:K,11,0) -> BINEKARAC | I3: =VLOOKUP(B3,Sayfa2!A:N,13,0) -> SUV RENAULT DUSTER EVOLUTION MILD HYBRID | J3: =VLOOKUP(B3,Sayfa2!A:AI,35,0) -> H5FA604D011963 | K3: =VLOOKUP(B3,Sayfa2!A:U,21,0) -> HP113619 | L3: =VLOOKUP(B3,Sayfa2!A:U,21,0) -> HP113619
A4: =VLOOKUP(B4,Sayfa2!A:O,15,0) -> 06EZE159 | B4: =Sayfa2!A5 -> BA-256 | C4: =VLOOKUP(B4,Sayfa2!A:G,7,0) -> 1038 | D4: =VLOOKUP(B4,Sayfa2!A:H,8,0) -> 138 | E4: =VLOOKUP(B4,Sayfa2!A:I,9,0) -> 10001038 | F4: =VLOOKUP(B4,Sayfa2!A:J,10,0) -> 1038-01 | G4: =IF(H4="BINEKARAC", 702001, IF(H4="CEKICI", 702002, IF(H4="KAMYON GRP", 702002, IF(H4="SERVISARAC", 702002, IF(H4="KAMYONET", 702011, 702003))))) -> 702001 | H4: =VLOOKUP(B4,Sayfa2!A:K,11,0) -> BINEKARAC | I4: =VLOOKUP(B4,Sayfa2!A:N,13,0) -> SUV RENAULT DUSTER EVOLUTION MILD HYBRID | J4: =VLOOKUP(B4,Sayfa2!A:AI,35,0) -> H5FA604D011871 | K4: =VLOOKUP(B4,Sayfa2!A:U,21,0) -> HP113621 | L4: =VLOOKUP(B4,Sayfa2!A:U,21,0) -> HP113621
A5: =VLOOKUP(B5,Sayfa2!A:O,15,0) -> 06GCT346 | B5: =Sayfa2!A6 -> BA-280 | C5: =VLOOKUP(B5,Sayfa2!A:G,7,0) -> 1038 | D5: =VLOOKUP(B5,Sayfa2!A:H,8,0) -> 138 | E5: =VLOOKUP(B5,Sayfa2!A:I,9,0) -> 10001038 | F5: =VLOOKUP(B5,Sayfa2!A:J,10,0) -> 1038-01 | G5: =IF(H5="BINEKARAC", 702001, IF(H5="CEKICI", 702002, IF(H5="KAMYON GRP", 702002, IF(H5="SERVISARAC", 702002, IF(H5="KAMYONET", 702011, 702003))))) -> 702001 | H5: =VLOOKUP(B5,Sayfa2!A:K,11,0) -> BINEKARAC | I5: =VLOOKUP(B5,Sayfa2!A:N,13,0) -> OTOMOBİL TOYOTA COROLLA CROSS 1.8 HYBRID | J5: =VLOOKUP(B5,Sayfa2!A:AI,35,0) -> 2ZR3K21305 | K5: =VLOOKUP(B5,Sayfa2!A:U,21,0) -> IM699026 | L5: =VLOOKUP(B5,Sayfa2!A:U,21,0) -> IM699026
A6: =VLOOKUP(B6,Sayfa2!A:O,15,0) -> 06CZN617 | B6: =Sayfa2!A7 -> CKC-035 | C6: =VLOOKUP(B6,Sayfa2!A:G,7,0) -> 1035 | D6: =VLOOKUP(B6,Sayfa2!A:H,8,0) -> 135 | E6: =VLOOKUP(B6,Sayfa2!A:I,9,0) -> 10001035 | F6: =VLOOKUP(B6,Sayfa2!A:J,10,0) -> 1035-01 | G6: =IF(H6="BINEKARAC", 702001, IF(H6="CEKICI", 702002, IF(H6="KAMYON GRP", 702002, IF(H6="SERVISARAC", 702002, IF(H6="KAMYONET", 702011, 702003))))) -> 702002 | H6: =VLOOKUP(B6,Sayfa2!A:K,11,0) -> CEKICI | I6: =VLOOKUP(B6,Sayfa2!A:N,13,0) -> ÇEKİCİ MERCEDES-BENZ ACTROS 1851 | J6: =VLOOKUP(B6,Sayfa2!A:AI,35,0) -> 471926C0652428 | K6: =VLOOKUP(B6,Sayfa2!A:U,21,0) -> GA891383 | L6: =VLOOKUP(B6,Sayfa2!A:U,21,0) -> GA891383
A7: =VLOOKUP(B7,Sayfa2!A:O,15,0) -> 06YON05 | B7: =Sayfa2!A8 -> SAD-001 | C7: =VLOOKUP(B7,Sayfa2!A:G,7,0) -> 1035 | D7: =VLOOKUP(B7,Sayfa2!A:H,8,0) -> 135 | E7: =VLOOKUP(B7,Sayfa2!A:I,9,0) -> 10001035 | F7: =VLOOKUP(B7,Sayfa2!A:J,10,0) -> 1035-01 | G7: =IF(H7="BINEKARAC", 702001, IF(H7="CEKICI", 702002, IF(H7="KAMYON GRP", 702002, IF(H7="SERVISARAC", 702002, IF(H7="KAMYONET", 702011, 702003))))) -> 702003 | H7: =VLOOKUP(B7,Sayfa2!A:K,11,0) -> DORSE GRUP | I7: =VLOOKUP(B7,Sayfa2!A:N,13,0) -> SAL DORSE SCHMITZ 13 -60 | J7: =VLOOKUP(B7,Sayfa2!A:AI,35,0) -> WSMS6080000504500 | K7: =VLOOKUP(B7,Sayfa2!A:U,21,0) -> GF398496 | L7: =VLOOKUP(B7,Sayfa2!A:U,21,0) -> GF398496
A8: =VLOOKUP(B8,Sayfa2!A:O,15,0) -> 34.00.17.17645 | B8: =Sayfa2!A9 -> BKL-011 | C8: =VLOOKUP(B8,Sayfa2!A:G,7,0) -> 1035 | D8: =VLOOKUP(B8,Sayfa2!A:H,8,0) -> 135 | E8: =VLOOKUP(B8,Sayfa2!A:I,9,0) -> 10001035 | F8: =VLOOKUP(B8,Sayfa2!A:J,10,0) -> 1035-01 | G8: =IF(H8="BINEKARAC", 702001, IF(H8="CEKICI", 702002, IF(H8="KAMYON GRP", 702002, IF(H8="SERVISARAC", 702002, IF(H8="KAMYONET", 702011, 702003))))) -> 702003 | H8: =VLOOKUP(B8,Sayfa2!A:K,11,0) -> IS MAKINE | I8: =VLOOKUP(B8,Sayfa2!A:N,13,0) -> BEKO LOADER HIDROMEK HMK 102S | J8: =VLOOKUP(B8,Sayfa2!A:AI,35,0) -> NM75621U291211C | K8: =VLOOKUP(B8,Sayfa2!A:U,21,0) -> B439604 | L8: =VLOOKUP(B8,Sayfa2!A:U,21,0) -> B439604
A9: =VLOOKUP(B9,Sayfa2!A:O,15,0) -> 34.00.12.5839 | B9: =Sayfa2!A10 -> BKL-012 | C9: =VLOOKUP(B9,Sayfa2!A:G,7,0) -> 1038 | D9: =VLOOKUP(B9,Sayfa2!A:H,8,0) -> 138 | E9: =VLOOKUP(B9,Sayfa2!A:I,9,0) -> 10001038 | F9: =VLOOKUP(B9,Sayfa2!A:J,10,0) -> 1038-01 | G9: =IF(H9="BINEKARAC", 702001, IF(H9="CEKICI", 702002, IF(H9="KAMYON GRP", 702002, IF(H9="SERVISARAC", 702002, IF(H9="KAMYONET", 702011, 702003))))) -> 702003 | H9: =VLOOKUP(B9,Sayfa2!A:K,11,0) -> IS MAKINE | I9: =VLOOKUP(B9,Sayfa2!A:N,13,0) -> BEKO LOADER HIDROMEK HMK 102S | J9: =VLOOKUP(B9,Sayfa2!A:AI,35,0) -> NM75147U160838W | K9: =VLOOKUP(B9,Sayfa2!A:U,21,0) -> B334307 | L9: =VLOOKUP(B9,Sayfa2!A:U,21,0) -> B334307
A10: =VLOOKUP(B10,Sayfa2!A:O,15,0) -> 34.00.20.3282 | B10: =Sayfa2!A11 -> BKL-021 | C10: =VLOOKUP(B10,Sayfa2!A:G,7,0) -> 1035 | D10: =VLOOKUP(B10,Sayfa2!A:H,8,0) -> 135 | E10: =VLOOKUP(B10,Sayfa2!A:I,9,0) -> 10001035 | F10: =VLOOKUP(B10,Sayfa2!A:J,10,0) -> 1035-01 | G10: =IF(H10="BINEKARAC", 702001, IF(H10="CEKICI", 702002, IF(H10="KAMYON GRP", 702002, IF(H10="SERVISARAC", 702002, IF(H10="KAMYONET", 702011, 702003))))) -> 702003 | H10: =VLOOKUP(B10,Sayfa2!A:K,11,0) -> IS MAKINE | I10: =VLOOKUP(B10,Sayfa2!A:N,13,0) -> BEKO LOADER HIDROMEK HMK 102S | J10: =VLOOKUP(B10,Sayfa2!A:AI,35,0) -> NM75621U331888F | K10: =VLOOKUP(B10,Sayfa2!A:U,21,0) -> B352494 | L10: =VLOOKUP(B10,Sayfa2!A:U,21,0) -> B352494
A11: =VLOOKUP(B11,Sayfa2!A:O,15,0) -> 34.00.20.9034. | B11: =Sayfa2!A12 -> BTF-001 | C11: =VLOOKUP(B11,Sayfa2!A:G,7,0) -> 1038 | D11: =VLOOKUP(B11,Sayfa2!A:H,8,0) -> 138 | E11: =VLOOKUP(B11,Sayfa2!A:I,9,0) -> 10001038 | F11: =VLOOKUP(B11,Sayfa2!A:J,10,0) -> 1038-01 | G11: =IF(H11="BINEKARAC", 702001, IF(H11="CEKICI", 702002, IF(H11="KAMYON GRP", 702002, IF(H11="SERVISARAC", 702002, IF(H11="KAMYONET", 702011, 702003))))) -> 702003 | H11: =VLOOKUP(B11,Sayfa2!A:K,11,0) -> IS MAKINE | I11: =VLOOKUP(B11,Sayfa2!A:N,13,0) -> BETON FINISHERI POWER CURBER 5700-D | J11: =VLOOKUP(B11,Sayfa2!A:AI,35,0) -> 746271167 | K11: =VLOOKUP(B11,Sayfa2!A:U,21,0) -> B438027 | L11: =VLOOKUP(B11,Sayfa2!A:U,21,0) -> B438027
A12: =VLOOKUP(B12,Sayfa2!A:O,15,0) -> 34.00.13.5612 | B12: =Sayfa2!A13 -> DZR-001 | C12: =VLOOKUP(B12,Sayfa2!A:G,7,0) -> 1038 | D12: =VLOOKUP(B12,Sayfa2!A:H,8,0) -> 138 | E12: =VLOOKUP(B12,Sayfa2!A:I,9,0) -> 10001038 | F12: =VLOOKUP(B12,Sayfa2!A:J,10,0) -> 1038-01 | G12: =IF(H12="BINEKARAC", 702001, IF(H12="CEKICI", 702002, IF(H12="KAMYON GRP", 702002, IF(H12="SERVISARAC", 702002, IF(H12="KAMYONET", 702011, 702003))))) -> 702003 | H12: =VLOOKUP(B12,Sayfa2!A:K,11,0) -> IS MAKINE | I12: =VLOOKUP(B12,Sayfa2!A:N,13,0) -> DOZER KOMATSU D155AX-6 | J12: =VLOOKUP(B12,Sayfa2!A:AI,35,0) -> 538159 | K12: =VLOOKUP(B12,Sayfa2!A:U,21,0) -> A645806 | L12: =VLOOKUP(B12,Sayfa2!A:U,21,0) -> A645806
A13: =VLOOKUP(B13,Sayfa2!A:O,15,0) -> 34.00.16.22897 | B13: =Sayfa2!A14 -> DZR-002 | C13: =VLOOKUP(B13,Sayfa2!A:G,7,0) -> 1035 | D13: =VLOOKUP(B13,Sayfa2!A:H,8,0) -> 135 | E13: =VLOOKUP(B13,Sayfa2!A:I,9,0) -> 10001035 | F13: =VLOOKUP(B13,Sayfa2!A:J,10,0) -> 1035-01 | G13: =IF(H13="BINEKARAC", 702001, IF(H13="CEKICI", 702002, IF(H13="KAMYON GRP", 702002, IF(H13="SERVISARAC", 702002, IF(H13="KAMYONET", 702011, 702003))))) -> 702003 | H13: =VLOOKUP(B13,Sayfa2!A:K,11,0) -> IS MAKINE | I13: =VLOOKUP(B13,Sayfa2!A:N,13,0) -> DOZER CATERPILLAR D7-R2 | J13: =VLOOKUP(B13,Sayfa2!A:AI,35,0) -> 7ZR26598 | K13: =VLOOKUP(B13,Sayfa2!A:U,21,0) -> A619619 | L13: =VLOOKUP(B13,Sayfa2!A:U,21,0) -> A619619
A14: =VLOOKUP(B14,Sayfa2!A:O,15,0) -> 34.00.19.12152 | B14: =Sayfa2!A15 -> DZR-004 | C14: =VLOOKUP(B14,Sayfa2!A:G,7,0) -> 1038 | D14: =VLOOKUP(B14,Sayfa2!A:H,8,0) -> 138 | E14: =VLOOKUP(B14,Sayfa2!A:I,9,0) -> 10001038 | F14: =VLOOKUP(B14,Sayfa2!A:J,10,0) -> 1038-01 | G14: =IF(H14="BINEKARAC", 702001, IF(H14="CEKICI", 702002, IF(H14="KAMYON GRP", 702002, IF(H14="SERVISARAC", 702002, IF(H14="KAMYONET", 702011, 702003))))) -> 702003 | H14: =VLOOKUP(B14,Sayfa2!A:K,11,0) -> IS MAKINE | I14: =VLOOKUP(B14,Sayfa2!A:N,13,0) -> DOZER KOMATSU D155AX-6 | J14: =VLOOKUP(B14,Sayfa2!A:AI,35,0) -> 542581 | K14: =VLOOKUP(B14,Sayfa2!A:U,21,0) -> B359952 | L14: =VLOOKUP(B14,Sayfa2!A:U,21,0) -> B359952
... A115: =VLOOKUP(B115,Sayfa2!A:O,15,0) | B115: =Sayfa2!A116 -> TRE-001 | C115: =VLOOKUP(B115,Sayfa2!A:G,7,0) -> 1035 | D115: =VLOOKUP(B115,Sayfa2!A:H,8,0) -> 135 | E115: =VLOOKUP(B115,Sayfa2!A:I,9,0) -> 10001035 | F115: =VLOOKUP(B115,Sayfa2!A:J,10,0) -> 1035-01 | G115: =IF(H115="BINEKARAC", 702001, IF(H115="CEKICI", 702002, IF(H115="KAMYON GRP", 702002, IF(H115="SERVISARAC", 702002, IF(H115="KAMYONET", 702011, 702003))))) -> 702003 | H115: =VLOOKUP(B115,Sayfa2!A:K,11,0) -> TESIS | I115: =VLOOKUP(B115,Sayfa2!A:N,13,0) -> TOPRAK ELEME AYMAK AGS-1245 | J115: =VLOOKUP(B115,Sayfa2!A:AI,35,0) | K115: =VLOOKUP(B115,Sayfa2!A:U,21,0) | L115: =VLOOKUP(B115,Sayfa2!A:U,21,0)

Sheet Sayfa2
A1: 1 | B1: 2 | C1: 3 | D1: 4 | E1: 5 | F1: 6 | G1: 7 | H1: 8 | I1: 9 | J1: 10 | K1: 11 | L1: 12 | M1: 13 | N1: 14 | O1: 15 | P1: 16 | Q1: 17 | R1: 18 | S1: 19 | T1: 20 | U1: 21 | V1: 22 | W1: 23 | X1: 24 | Y1: 25 | Z1: 26 | AA1: 27 | AB1: 28 | AC1: 29 | AD1: 30 | AE1: 31 | AF1: 32 | AG1: 33 | AH1: 34 | AI1: 35 | AJ1: 36 | AK1: 37 | AL1: 38 | AM1: 39 | AN1: 40 | AO1: 41 | AP1: 42 | AQ1: 43 | AR1: 44 | AS1: 45 | AT1: 46 | AU1: 47
B2: Şirket kodu | C2: BO üretim yeri | D2: Geçerlilik bşl. | E2: Geçerlilik sonu | F2: Aktivite türü | G2: Planlama ÜY | H2: Planlama grubu | I2: Masraf yeri | J2: Sorumlu işyeri | K2: Nesne türü | L2: Ekipman | M2: Tanım | N2: Tip tanımı | O2: Taşıt plaka no. | P2: Üretici | Q2: Yapım yılı | R2: Ekipman tipi | S2: Teknik Nesne Türü | T2: Sistem durumu | U2: Ruhsat Seri No | V2: Taşıt Takip Sistem A | W2: Taşıt Takip IMEI | X2: Leasing Bitiş Tarihi | Y2: ABC göstergesi | Z2: Acenta Bilgisi | AA2: Acenta Bilgisi24 | AB2: Aylık Kullanım Bedel | AC2: Başlangıç Tarihi | AD2: Başlangıç Tarihi27 | AE2: Bitiş Tarihi | AF2: Bitiş Tarihi29 | AG2: Makine Durumu | AH2: Mal Sahibi | AI2: Motor seri no. | AJ2: Per.Muayene bitiş Tr | AK2: Plan Kira PB | AL2: Poliçe No | AM2: Poliçe No36 | AN2: Prim Tutarı | AO2: Prim Tutarı38 | AP2: Ruhsat Sahibi | AQ2: Satınalma dğr. | AR2: Satınalma trh. | AS2: Sigorta Sirketi | AT2: Sigorta Sirketi43 | AU2: Ş
A3: =L3 -> BA-090 | B3: 1000 | C3: 1001 | D3: 46207 | E3: 2958465 | F3: EQ2215 | G3: 1035 | H3: 135 | I3: 10001035 | J3: 1035-01 | K3: BINEKARAC | L3: BA-090 | M3: OTOMOBİL FIAT EGEA 1.3 MULTIJET | N3: EGEA | O3: 06CBB253 | P3: FIAT | R3: T | S3: OTOMOBİL | T3: KLNB | U3: FP303298 | W3: 000000000000000000000000000000 | Z3: SERAY SİGORTA ARACILIK HİZM.LT | AA3: SERAY SİGORTA ARACILIK HİZM.LT | AB3: 30000 | AC3: 45942 | AD3: 45911 | AE3: 46307 | AF3: 46276 | AG3: GRUP MAKİNELERİ | AH3: KLV A.Ş. | AJ3: 46580 | AK3: TRY | AL3: 1830953310 | AM3: 1818196471 | AN3: 8640.47 | AO3: 8640.47 | AP3: KLV A.Ş. | AQ3: 770000 | AR3: 45191 | AS3: SER-AY SİGORTA ARACILIK HİZM. | AT3: SER-AY SİGORTA ARACILIK HİZM. | AU3: ZFA35600006S14994
A4: =L4 -> BA-254 | B4: 1000 | C4: 1001 | D4: 46119 | E4: 2958465 | F4: EQ3489 | G4: 1035 | H4: 135 | I4: 10001035 | J4: 1035-01 | K4: BINEKARAC | L4: BA-254 | M4: SUV RENAULT DUSTER EVOLUTION MILD HYBRID | N4: DUSTER | O4: 06EZE162 | P4: RENAULT | Q4: 2024 | R4: T | S4: SUV | T4: KLNB | U4: HP113619 | W4: 000000000000000000000000000000 | Z4: SERAY SİGORTA ARACILIK HİZM.LT | AA4: SERAY SİGORTA ARACILIK HİZM.LT | AB4: 0 | AC4: 46018 | AD4: 46018 | AE4: 46383 | AF4: 46276 | AG4: GRUP MAKİNELERİ | AH4: KLV A.Ş. | AI4: H5FA604D011963 | AJ4: 46727 | AL4: 1864377720 | AM4: 1854673610 | AN4: 8780.02 | AO4: 12681.09 | AP4: KLV A.Ş. | AQ4: 1480000 | AR4: 45652 | AS4: SER-AY SİGORTA ARACILIK HİZM. | AT4: SER-AY SİGORTA ARACILIK HİZM. | AU4: VF1RJF01974008969
A5: =L5 -> BA-256 | B5: 1000 | C5: 1001 | D5: 46234 | E5: 2958465 | F5: EQ3491 | G5: 1038 | H5: 138 | I5: 10001038 | J5: 1038-01 | K5: BINEKARAC | L5: BA-256 | M5: SUV RENAULT DUSTER EVOLUTION MILD HYBRID | N5: DUSTER | O5: 06EZE159 | P5: RENAULT | Q5: 2024 | R5: T | S5: SUV | T5: KLNB | U5: HP113621 | W5: 000000000000000000000000000000 | Z5: SERAY SİGORTA ARACILIK HİZM.LT | AA5: SERAY SİGORTA ARACILIK HİZM.LT | AB5: 0 | AC5: 46018 | AD5: 46018 | AE5: 46383 | AF5: 46276 | AG5: GRUP MAKİNELERİ | AH5: KLV A.Ş. | AI5: H5FA604D011871 | AJ5: 46727 | AL5: 1864383960 | AM5: 1854678950 | AN5: 8780.02 | AO5: 12681.09 | AP5: KLV A.Ş. | AQ5: 1480000 | AR5: 45652 | AS5: SER-AY SİGORTA ARACILIK HİZM. | AT5: SER-AY SİGORTA ARACILIK HİZM. | AU5: VF1RJF01074008956
A6: =L6 -> BA-280 | B6: 1000 | C6: 1001 | D6: 46239 | E6: 2958465 | F6: EQ3884 | G6: 1038 | H6: 138 | I6: 10001038 | J6: 1038-01 | K6: BINEKARAC | L6: BA-280 | M6: OTOMOBİL TOYOTA COROLLA CROSS 1.8 HYBRID | N6: COROLLA CROSS 1.8 HY | O6: 06GCT346 | P6: TOYOTA | Q6: 2026 | R6: T | S6: OTOMOBİL | T6: KLNB | U6: IM699026 | W6: 000000000000000000000000000000 | AB6: 0 | AG6: GRUP MAKİNELERİ | AH6: KLV A.Ş. | AI6: 2ZR3K21305 | AJ6: 47233 | AN6: 0 | AO6: 0 | AP6: ALBARAKA TÜRK KATILIM BANKASI | AQ6: 2550000 | AR6: 46234 | AU6: JTNADADB709036009
A7: =L7 -> CKC-035 | B7: 1000 | C7: 1001 | D7: 46190 | E7: 2958465 | F7: EQ2506 | G7: 1035 | H7: 135 | I7: 10001035 | J7: 1035-01 | K7: CEKICI | L7: CKC-035 | M7: ÇEKİCİ MERCEDES-BENZ ACTROS 1851 | N7: ACTROS 1851 | O7: 06CZN617 | P7: MERCEDES-BENZ | Q7: 2021 | R7: T | S7: ÇEKİCİ | T7: KLNB | U7: GA891383 | W7: 000000000000000000000000000000 | Z7: SERAY SİGORTA ARACILIK HİZM.LT | AA7: SERAY SİGORTA ARACILIK HİZM.LT | AB7: 250000 | AC7: 46143 | AD7: 45911 | AE7: 46503 | AF7: 46276 | AG7: GRUP MAKİNELERİ | AH7: KLV A.Ş. | AI7: 471926C0652428 | AJ7: 46601 | AK7: TRY | AL7: 1928830850 | AM7: 1818210391 | AN7: 48473.01 | AO7: 44068.46 | AP7: FİBA BANKA ANKARA KURUMSAL ŞUB | AQ7: 4100000 | AR7: 45183 | AS7: SER-AY SİGORTA ARACILIK HİZM. | AT7: SER-AY SİGORTA ARACILIK HİZM. | AU7: NMB96340312210319
A8: =L8 -> SAD-001 | B8: 1000 | C8: 1001 | D8: 46190 | E8: 2958465 | F8: EQ1710 | G8: 1035 | H8: 135 | I8: 10001035 | J8: 1035-01 | K8: DORSE GRUP | L8: SAD-001 | M8: SAL DORSE SCHMITZ 13 -60 | N8: SPR24 | O8: 06YON05 | P8: SCHMITZ | Q8: 2003 | R8: T | S8: SAL DORSE | T8: KLNB | U8: GF398496 | V8: YOK | W8: 000000000000000000000000000000 | Z8: RÖMORK/ TRAFIK YOK | AA8: SERAY SİGORTA ARACILIK HİZM.LT | AB8: 0 | AD8: 45911 | AF8: 46276 | AG8: GRUP MAKİNELERİ | AH8: KLV A.Ş. | AI8: WSMS6080000504500 | AJ8: 46400 | AM8: 1818285271 | AN8: 0 | AO8: 9500.01 | AP8: KLV A.Ş. | AQ8: 350000 | AR8: 45189 | AT8: SER-AY SİGORTA ARACILIK HİZM. | AU8: 6816
A9: =L9 -> BKL-011 | B9: 1000 | C9: 1001 | D9: 46252 | E9: 2958465 | F9: EQ0197 | G9: 1035 | H9: 135 | I9: 10001035 | J9: 1035-01 | K9: IS MAKINE | L9: BKL-011 | M9: BEKO LOADER HIDROMEK HMK 102S | N9: HMK 102S ALPHA | O9: 34.00.17.17645 | P9: HIDROMEK | Q9: 2017 | R9: T | S9: BEKO LOADER | T9: KLNB | U9: B439604 | V9: YOK | W9: 000000000000000000000000000000 | Z9: SERAY SİGORTA ARACILIK HİZM.LT | AA9: SERAY SİGORTA ARACILIK HİZMET | AB9: 110000 | AC9: 45231 | AD9: 44074 | AE9: 45595 | AF9: 44439 | AG9: GRUP MAKİNELERİ | AH9: KLV A.Ş. | AI9: NM75621U291211C | AK9: TRY | AL9: 1487291823 | AM9: 178108620 | AN9: 3030 | AO9: 0 | AP9: KLV A.Ş. | AQ9: 2200000 | AR9: 45183 | AS9: SER-AY SİGORTA ARACILIK HİZM. | AU9: HMK102SHA2S092050
A10: =L10 -> BKL-012 | B10: 1000 | C10: 1001 | D10: 46244 | E10: 2958465 | F10: EQ0198 | G10: 1038 | H10: 138 | I10: 10001038 | J10: 1038-01 | K10: IS MAKINE | L10: BKL-012 | M10: BEKO LOADER HIDROMEK HMK 102S | N10: HMK 102S ALPHA | O10: 34.00.12.5839 | P10: HIDROMEK | Q10: 2012 | R10: T | S10: BEKO LOADER | T10: KLNB | U10: B334307 | V10: YOK | W10: 000000000000000000000000000000 | Z10: SER-AY SİGORTA ARACILIK HİZME | AA10: SERAY SİGORTA ARACILIK HİZMET | AB10: 110000 | AC10: 45960 | AD10: 44074 | AE10: 46325 | AF10: 44439 | AG10: GRUP MAKİNELERİ | AH10: KLV A.Ş. | AI10: NM75147U160838W | AK10: TRY | AL10: 1840647551 | AM10: 178108620 | AN10: 11361 | AO10: 0 | AP10: KLV A.Ş. | AQ10: 1500000 | AR10: 45183 | AS10: SER-AY SİGORTA ARACILIK HİZM. | AU10: HMK102STV35A80339
A11: =L11 -> BKL-021 | B11: 1000 | C11: 1001 | D11: 46223 | E11: 2958465 | F11: EQ0207 | G11: 1035 | H11: 135 | I11: 10001035 | J11: 1035-01 | K11: IS MAKINE | L11: BKL-021 | M11: BEKO LOADER HIDROMEK HMK 102S | N11: HMK 102S | O11: 34.00.20.3282 | P11: HIDROMEK | Q11: 2020 | R11: T | S11: BEKO LOADER | T11: KLNB | U11: B352494 | V11: YOK | W11: 000000000000000000000000000000 | X11: 45657 | Z11: HDİ SİGORTA A.Ş. | AA11: SERAY SİGORTA ARACILIK HİZM.LT | AB11: 110000 | AC11: 45901 | AD11: 45011 | AE11: 46255 | AF11: 45377 | AG11: GRUP MAKİNELERİ | AH11: KLV A.Ş. | AI11: NM75621U331888F | AK11: TRY | AL11: 912174448 | AM11: 1154345923 | AN11: 12346.44 | AO11: 2593.45 | AP11: TÜRKİYE FİNANS KATILIM BANKASI | AQ11: 2900000 | AR11: 45183 | AS11: HDI SİGORTA | AT11: SER-AY SİGORTA ARACILIK HİZM. | AU11: HMK102SLP2S093180
A12: =L12 -> BTF-001 | B12: 1000 | C12: 1001 | D12: 46253 | E12: 2958465 | F12: EQ0217 | G12: 1038 | H12: 138 | I12: 10001038 | J12: 1038-01 | K12: IS MAKINE | L12: BTF-001 | M12: BETON FINISHERI POWER CURBER 5700-D | N12: 5700-D | O12: 34.00.20.9034. | P12: POWER CURBER | Q12: 2020 | R12: T | S12: BETON FİNİŞERİ | T12: KLNB | U12: B438027 | V12: YOK | W12: 000000000000000000000000000000 | AA12: SERAY SİGORTA ARACILIK HİZMET | AB12: 350000 | AD12: 44074 | AF12: 44439 | AG12: GRUP MAKİNELERİ | AH12: KLV A.Ş. | AI12: 746271167 | AK12: TRY | AM12: 178108620 | AN12: 0 | AO12: 0 | AP12: KLV A.Ş. | AQ12: 350000 | AR12: 45183 | AU12: 57D01-20-0543023
A13: =L13 -> DZR-001 | B13: 1000 | C13: 1001 | D13: 46253 | E13: 2958465 | F13: EQ0526 | G13: 1038 | H13: 138 | I13: 10001038 | J13: 1038-01 | K13: IS MAKINE | L13: DZR-001 | M13: DOZER KOMATSU D155AX-6 | N13: D155AX-6 | O13: 34.00.13.5612 | P13: KOMATSU | Q13: 2011 | R13: T | S13: DOZER | T13: KLNB | U13: A645806 | V13: YOK | W13: 000000000000000000000000000000 | AA13: SERAY SİGORTA ARACILIK HİZMET | AB13: 450000 | AD13: 44074 | AF13: 44439 | AG13: GRUP MAKİNELERİ | AH13: KLV A.Ş. | AI13: 538159 | AK13: TRY | AM13: 178108620 | AN13: 0 | AO13: 0 | AP13: KLV A.Ş. | AQ13: 260000 | AR13: 45185 | AU13: 81432
A14: =L14 -> DZR-002 | B14: 1000 | C14: 1001 | D14: 46107 | E14: 2958465 | F14: EQ0527 | G14: 1035 | H14: 135 | I14: 10001035 | J14: 1035-01 | K14: IS MAKINE | L14: DZR-002 | M14: DOZER CATERPILLAR D7-R2 | N14: D7-R2 | O14: 34.00.16.22897 | P14: CATERPILLAR | Q14: 2011 | R14: T | S14: DOZER | T14: KLNB | U14: A619619 | V14: YOK | W14: 000000000000000000000000000000 | AA14: SERAY SİGORTA ARACILIK HİZMET | AB14: 400000 | AD14: 44074 | AF14: 44439 | AG14: GRUP MAKİNELERİ | AH14: KLV A.Ş. | AI14: 7ZR26598 | AK14: TRY | AM14: 178108620 | AN14: 0 | AO14: 0 | AP14: KLV A.Ş. | AQ14: 160000 | AR14: 45236 | AU14: BRM01017
A15: =L15 -> DZR-004 | B15: 1000 | C15: 1001 | D15: 46244 | E15: 2958465 | F15: EQ0529 | G15: 1038 | H15: 138 | I15: 10001038 | J15: 1038-01 | K15: IS MAKINE | L15: DZR-004 | M15: DOZER KOMATSU D155AX-6 | N15: D155AX-6 | O15: 34.00.19.12152 | P15: KOMATSU | Q15: 2019 | R15: T | S15: DOZER | T15: KLNB | U15: B359952 | V15: YOK | W15: 000000000000000000000000000000 | X15: 45322 | AA15: SERAY SİGORTA ARACILIK HİZMET | AB15: 450000 | AD15: 44074 | AF15: 44439 | AG15: GRUP MAKİNELERİ | AH15: KLV A.Ş. | AI15: 542581 | AK15: TRY | AM15: 178108620 | AN15: 0 | AO15: 0 | AP15: KLV A.Ş. | AQ15: 260000 | AR15: 45185 | AU15: 82152
A16: =L16 -> EKS-011 | B16: 1000 | C16: 1001 | D16: 46255 | E16: 2958465 | F16: EQ0564 | G16: 1038 | H16: 138 | I16: 10001038 | J16: 1038-01 | K16: IS MAKINE | L16: EKS-011 | M16: EKSCAVATOR HITACHI ZX 490 H-5A | N16: ZX 490 H-5A | O16: 34.00.17.5310 | P16: HITACHI | Q16: 2017 | R16: T | S16: EKSCAVATÖR | T16: KLNB | U16: B439613 | V16: YOK | W16: 000000000000000000000000000000 | X16: 44316 | AA16: SERAY SİGORTA ARACILIK HİZMET | AB16: 350000 | AD16: 44074 | AF16: 44439 | AG16: GRUP MAKİNELERİ | AH16: KLV A.Ş. | AI16: 527895 | AK16: TRY | AM16: 178109420 | AN16: 0 | AO16: 0 | AP16: KLV A.Ş. | AQ16: 230000 | AR16: 45236 | AU16: HCMJAE90K00060169
A17: =L17 -> EKS-013 | B17: 1000 | C17: 1001 | D17: 46261 | E17: 2958465 | F17: EQ0566 | G17: 1035 | H17: 135 | I17: 10001035 | J17: 1035-01 | K17: IS MAKINE | L17: EKS-013 | M17: EKSCAVATOR HITACHI ZX 210 H-5A | N17: ZX 210 H-5A | O17: 34.00.17.5313 | P17: HITACHI | Q17: 2017 | R17: T | S17: EKSCAVATÖR | T17: KLNB | U17: B321974 | V17: YOK | W17: 000000000000000000000000000000 | X17: 44316 | Z17: SERAY SİGORTA ARACILIK HİZM.LT | AA17: SERAY SİGORTA ARACILIK HİZMET | AB17: 200000 | AC17: 46169 | AD17: 44074 | AE17: 46534 | AF17: 44439 | AG17: GRUP MAKİNELERİ | AH17: PROYAP A.Ş. | AI17: 747628 | AK17: TRY | AL17: 1962985630 | AM17: 178109420 | AN17: 9984 | AO17: 0 | AP17: TÜRKİYE FİNANS KATILIM BANKASI | AQ17: 3100000 | AR17: 45236 | AS17: SER-AY SİGORTA ARACILIK HİZM. | AU17: HCMDCX92E00300187
A18: =L18 -> FRK-005 | B18: 1000 | C18: 1001 | D18: 46261 | E18: 2958465 | F18: EQ2901 | G18: 1035 | H18: 135 | I18: 10001035 | J18: 1035-01 | K18: IS MAKINE | L18: FRK-005 | M18: FORKLIFT JCB TELEHANDLER | N18: 540V180 | O18: 34.00.23.12753 | Q18: 2023 | R18: T | S18: FORKLİFT | T18: KLNB | U18: B352498 | W18: 000000000000000000000000000000 | AB18: 200000 | AG18: GRUP MAKİNELERİ | AH18: KLV A.Ş. | AI18: 41840U1129223 | AK18: TRY | AN18: 0 | AO18: 0 | AP18: TÜRKİYE FİNANS KATILIM BANKASI | AQ18: 140000 | AR18: 45236 | AU18: JCB5RANGLP3241618
A19: =L19 -> GRY-009 | B19: 1000 | C19: 1001 | D19: 46226 | E19: 2958465 | F19: EQ0625 | G19: 1035 | H19: 135 | I19: 10001035 | J19: 1035-01 | K19: IS MAKINE | L19: GRY-009 | M19: GREYDER CATERPILLAR 12 H | N19: 12 H | O19: 34.00.13.3087 | P19: CATERPILLAR | Q19: 2000 | R19: T | S19: GREYDER | T19: KLNB | U19: A582318 | V19: YOK | W19: 000000000000000000000000000000 | Z19: SERAY SİGORTA ARACILIK HİZM.LT | AA19: SERAY SİGORTA ARACILIK HİZMET | AB19: 250000 | AC19: 44725 | AD19: 44074 | AE19: 45090 | AF19: 44439 | AG19: GRUP MAKİNELERİ | AH19: KLV A.Ş. | AI19: 6NC17431 | AK19: TRY | AL19: 1276888322 | AM19: 178111020 | AN19: 1803.45 | AO19: 0 | AP19: KLV A.Ş. | AQ19: 110000 | AR19: 45185 | AS19: SER-AY SİGORTA ARACILIK HİZM. | AU19: 2GS00418
A20: =L20 -> GRY-010 | B20: 1000 | C20: 1001 | D20: 46254 | E20: 2958465 | F20: EQ0626 | G20: 1038 | H20: 138 | I20: 10001038 | J20: 1038-01 | K20: IS MAKINE | L20: GRY-010 | M20: GREYDER CATERPILLAR 12 H | N20: 12 H | O20: 34.00.11.3626 | P20: CATERPILLAR | Q20: 2005 | R20: T | S20: GREYDER | T20: KLNB | U20: A412128 | V20: YOK | W20: 000000000000000000000000000000 | Z20: SERAY SİGORTA ARACILIK HİZM.LT | AA20: SERAY SİGORTA ARACILIK HİZMET | AB20: 250000 | AC20: 45313 | AD20: 44074 | AE20: 45679 | AF20: 44439 | AG20: GRUP MAKİNELERİ | AH20: KLV A.Ş. | AI20: 4ZF18367 | AK20: TRY | AL20: 1038381224 | AM20: 178111020 | AN20: 9221 | AO20: 0 | AP20: KLV A.Ş. | AQ20: 120000 | AR20: 45185 | AS20: SER-AY SİGORTA ARACILIK HİZM. | AU20: AMZ00670
A21: =L21 -> KIR-906 | B21: 1000 | C21: 1035 | D21: 46216 | E21: 2958465 | F21: EQ3587 | G21: 1035 | H21: 135 | I21: 10001035 | J21: 1035-01 | K21: IS MAKINE | L21: KIR-906 | M21: EKSCAVATOR CATERPILLAR 336 D | N21: 336 D | O21: 34.00.11.4461 | P21: CATERPILLAR | Q21: 2011 | R21: T | S21: EKSCAVATÖR | T21: KLNB | W21: 000000000000000000000000000000 | AB21: 0 | AG21: KİRALIK | AH21: MTD İŞ MAKİNALARI MÜH. SAN.TİC | AN21: 0 | AO21: 0 | AP21: MTD İŞ MAKİNALARI MÜH. SAN.TİC | AQ21: 0 | AU21: 308316/0PPN00510
A22: =L22 -> KIR-989 | B22: 1000 | C22: 1035 | D22: 46216 | E22: 2958465 | F22: EQ3793 | G22: 1035 | H22: 135 | I22: 10001035 | J22: 1035-01 | K22: IS MAKINE | L22: KIR-989 | M22: EKSCAVATOR HITACHI ZX490LCH-5A | N22: ZX490LCH-5A | P22: HITACHI | Q22: 2020 | R22: T | S22: EKSCAVATÖR | T22: KLNB | W22: 000000000000000000000000000000 | AB22: 0 | AG22: KİRALIK | AH22: AFS İŞ MAKİNELERİ YEDEK PARÇA | AN22: 0 | AO22: 0 | AP22: AFS İŞ MAKİNELERİ YEDEK PARÇA | AQ22: 0 | AU22: HCMJAE91L0061080
A23: =L23 -> LEKS-004 | B23: 1000 | C23: 1001 | D23: 46247 | E23: 2958465 | F23: EQ3082 | G23: 1038 | H23: 138 | I23: 10001038 | J23: 1038-01 | K23: IS MAKINE | L23: LEKS-004 | M23: LASTİKLİ EKSCAVATOR HİDROMEK 210W-5 | N23: 210W-5 | O23: 34.00.23.26389 | P23: HİDROMEK | Q23: 2023 | R23: T | S23: EKSCAVATÖR-LASTİKLİ | T23: KLNB | U23: B398363 | W23: 000000000000000000000000000000 | Z23: SERAY SİGORTA ARACILIK HİZM.LT | AB23: 200000 | AC23: 45980 | AE23: 46345 | AG23: GRUP MAKİNELERİ | AH23: KLV A.Ş. | AI23: 864694 | AK23: TRY | AL23: 1849647300 | AN23: 9562.5 | AO23: 0 | AP23: KLV A.Ş. | AQ23: 180000 | AR23: 45280 | AS23: SER-AY SİGORTA ARACILIK HİZM. | AU23: HMKH2280CP1225032
A24: =L24 -> LSY-001 | B24: 1000 | C24: 1001 | D24: 46244 | E24: 2958465 | F24: EQ1522 | G24: 1038 | H24: 138 | I24: 10001038 | J24: 1038-01 | K24: IS MAKINE | L24: LSY-001 | M24: LASTİKLİ YÜKLEYİCİ CATERPILLAR 950 GC | N24: 950 GC | O24: 34.00.17.13704 | P24: CATERPILLAR | Q24: 2016 | R24: T | S24: LASTİKLİ YÜKLEYİCİ | T24: KLNB | U24: A489379 | V24: YOK | W24: 000000000000000000000000000000 | X24: 44408 | Z24: SERAY SİGORTA ARACILIK HİZM.LT | AA24: SERAY SİGORTA ARACILIK HİZMET | AB24: 320000 | AC24: 45757 | AD24: 44074 | AE24: 46122 | AF24: 44439 | AG24: GRUP MAKİNELERİ | AH24: KLV A.Ş. | AI24: E7A05139 | AK24: TRY | AL24: 1757074560 | AM24: 178108620 | AN24: 5766 | AO24: 0 | AP24: GARANTİ FİNANSAL KİRALAMA ANOM | AQ24: 140000 | AR24: 45183 | AS24: SER-AY SİGORTA ARACILIK HİZM. | AU24: M5K01030
A25: =L25 -> LSY-003 | B25: 2000 | C25: 2001 | D25: 46269 | E25: 2958465 | F25: EQ1524 | G25: 1035 | H25: 135 | I25: 10001035 | J25: 1035-01 | K25: IS MAKINE | L25: LSY-003 | M25: LASTİKLİ YÜKLEYİCİ KOMATSU WA380-3 T3 A | N25: WA380-3 T3 A | O25: 34.00.18.8856 | P25: KOMATSU | Q25: 2018 | R25: T | S25: LASTİKLİ YÜKLEYİCİ | T25: KLNB | U25: B319167 | V25: YOK | W25: 000000000000000000000000000000 | Z25: SERAY SİGORTA ARACILIK HİZM.LT | AA25: SERAY SİGORTA ARACILIK HİZMET | AB25: 320000 | AC25: 45061 | AD25: 44074 | AE25: 45427 | AF25: 44439 | AG25: GRUP MAKİNELERİ | AH25: PROYAP A.Ş. | AI25: 26680299 | AK25: TRY | AL25: 1243984023 | AM25: 178109420 | AN25: 5517.45 | AO25: 0 | AP25: GARANTİ FİNANSAL KİRALAMA ANOM | AQ25: 160000 | AR25: 45183 | AS25: SER-AY SİGORTA ARACILIK HİZM. | AU25: 67773
A26: =L26 -> LSY-008 | B26: 1000 | C26: 1001 | D26: 46107 | E26: 2958465 | F26: EQ1529 | G26: 1035 | H26: 135 | I26: 10001035 | J26: 1035-01 | K26: IS MAKINE | L26: LSY-008 | M26: LASTİKLİ YÜKLEYİCİ KAWASAKI 90Z6 | N26: 90Z6 | O26: 34.00.16.21270 | P26: KAWASAKI | Q26: 2016 | R26: T | S26: LASTİKLİ YÜKLEYİCİ | T26: KLNB | U26: B321959 | V26: YOK | W26: 000000000000000000000000000000 | Z26: SERAY SİGORTA ARACILIK HİZM.LT | AA26: SERAY SİGORTA ARACILIK HİZMET | AB26: 320000 | AC26: 46169 | AD26: 44074 | AE26: 46534 | AF26: 44439 | AG26: GRUP MAKİNELERİ | AH26: KLV A.Ş. | AI26: 35337278 | AK26: TRY | AL26: 1962981750 | AM26: 178108620 | AN26: 9984 | AO26: 0 | AP26: TÜRKİYE FİNANS KATILIM BANKASI | AQ26: 185000 | AR26: 45183 | AS26: SER-AY SİGORTA ARACILIK HİZM. | AU26: 90C79020
A27: =L27 -> MNY-005 | B27: 1000 | C27: 1001 | D27: 46205 | E27: 2958465 | F27: EQ1581 | G27: 1035 | H27: 135 | I27: 10001035 | J27: 1035-01 | K27: IS MAKINE | L27: MNY-005 | M27: MİNİ YÜKLEYİCİ MUSTANG SL 2076 DXT | N27: SL 2076 DXT | O27: 34.00.15.4767 | P27: MUSTANG | Q27: 2011 | R27: T | S27: MİNİ YÜKLEYİCİ | T27: KLNB | U27: A610274 | V27: YOK | W27: 000000000000000000000000000000 | Z27: SERAY SİGORTA ARACILIK HİZM.LT | AA27: SERAY SİGORTA ARACILIK HİZMET | AB27: 70000 | AC27: 44830 | AD27: 44074 | AE27: 45195 | AF27: 44439 | AG27: GRUP MAKİNELERİ | AH27: KLV A.Ş. | AI27: H8825 | AK27: TRY | AL27: 1473692222 | AM27: 178109720 | AN27: 3384.45 | AO27: 0 | AP27: KLV A.Ş. | AQ27: 350000 | AR27: 45189 | AS27: SER-AY SİGORTA ARACILIK HİZM. | AU27: NMC02076B00006211
A28: =L28 -> TSL-003 | B28: 1000 | C28: 1001 | D28: 46252 | E28: 2958465 | F28: EQ1828 | G28: 1035 | H28: 135 | I28: 10001035 | J28: 1035-01 | K28: IS MAKINE | L28: TSL-003 | M28: TOPRAK SİLİNDİRİ BOMAG BW 213 D-5 | N28: BW 213 D-5 | O28: 34.00.17.6419 | P28: BOMAG | Q28: 2017 | R28: T | S28: TOPRAK SİLİNDİRİ | T28: KLNB | U28: B439608 | V28: YOK | W28: 000000000000000000000000000000 | Z28: SERAY SİGORTA ARACILIK HİZM.LT | AA28: SERAY SİGORTA ARACILIK HİZMET | AB28: 110000 | AC28: 45430 | AD28: 44074 | AE28: 45795 | AF28: 44439 | AG28: GRUP MAKİNELERİ | AH28: KLV A.Ş. | AI28: 11995399 | AK28: TRY | AL28: 1220068424 | AM28: 178109420 | AN28: 4330 | AO28: 0 | AP28: KLV A.Ş. | AQ28: 80000 | AR28: 45189 | AS28: SER-AY SİGORTA ARACILIK HİZM. | AU28: 101586481122
A29: =L29 -> TSL-008 | B29: 1000 | C29: 1001 | D29: 46244 | E29: 2958465 | F29: EQ1833 | G29: 1038 | H29: 138 | I29: 10001038 | J29: 1038-01 | K29: IS MAKINE | L29: TSL-008 | M29: TOPRAK SİLİNDİRİ BOMAG BW 216 D-5 | N29: BW 216 D-5 | O29: 34.00.17.22082 | P29: BOMAG | Q29: 2017 | R29: T | S29: TOPRAK SİLİNDİRİ | T29: KLNB | U29: B334300 | V29: YOK | W29: 000000000000000000000000000000 | Z29: SERAY SİGORTA ARACILIK HİZM.LT | AA29: SERAY SİGORTA ARACILIK HİZMET | AB29: 110000 | AC29: 45990 | AD29: 44074 | AE29: 46355 | AF29: 44439 | AG29: GRUP MAKİNELERİ | AH29: KLV A.Ş. | AI29: 12064512 | AK29: TRY | AL29: 1854050220 | AM29: 178108620 | AN29: 10198.98 | AO29: 0 | AP29: KLV A.Ş. | AQ29: 90000 | AR29: 45189 | AS29: SER-AY SİGORTA ARACILIK HİZM. | AU29: 101586261107
A30: =L30 -> TSL-020 | B30: 1000 | C30: 1001 | D30: 46266 | E30: 2958465 | F30: EQ1845 | G30: 1038 | H30: 138 | I30: 10001038 | J30: 1038-01 | K30: IS MAKINE | L30: TSL-020 | M30: TOPRAK SİLİNDİRİ BOMAG BW213DH-5 | N30: BW213DH-5 | O30: 34.00.20.3985 | P30: BOMAG | Q30: 2020 | R30: T | S30: TOPRAK SİLİNDİRİ | T30: KLNB | U30: B334132 | V30: YOK | W30: 000000000000000000000000000000 | X30: 45777 | Z30: SER-AY SİGORTA ARACILIK HİZME | AA30: SERAY SİGORTA ARACILIK HİZMET | AB30: 110000 | AC30: 45960 | AD30: 44074 | AE30: 46325 | AF30: 44439 | AG30: GRUP MAKİNELERİ | AH30: KLV A.Ş. | AI30: 12403069 | AK30: TRY | AL30: 1840658710 | AM30: 178108620 | AN30: 6312 | AO30: 0 | AP30: KLV A.Ş. | AQ30: 95000 | AR30: 45189 | AS30: SER-AY SİGORTA ARACILIK HİZM. | AU30: 101586721013
A31: =L31 -> LTW-010 | B31: 1000 | C31: 1001 | D31: 46126 | E31: 2958465 | F31: EQ1547 | G31: 1035 | H31: 135 | I31: 10001035 | J31: 1035-01 | K31: ISIK KULE | L31: LTW-010 | M31: AYDINLATMA KULESİ CHICAGO PNEUMATIC | N31: CPLT V15 MH - 5.4 KW | O31: WUX916185 | P31: CHICAGO PNEUMATIC | Q31: 2018 | R31: T | S31: AYDINLATMA KULESİ | T31: KLNB | V31: YOK | W31: 000000000000000000000000000000 | AB31: 25000 | AG31: GRUP MAKİNELERİ | AH31: KLV A.Ş. | AK31: TRY | AN31: 0 | AO31: 0 | AP31: KLV A.Ş. | AQ31: 0 | AU31: WUX916185
A32: =L32 -> LTW-013 | B32: 1000 | C32: 1001 | D32: 46128 | E32: 2958465 | F32: EQ1550 | G32: 1035 | H32: 135 | I32: 10001035 | J32: 1035-01 | K32: ISIK KULE | L32: LTW-013 | M32: AYDINLATMA KULESİ WACKER NEUSON 8 KW | N32: LTS8L - 8 KW - DIZEL | O32: 18201141 | P32: WACKER NEUSON | Q32: 2019 | R32: T | S32: AYDINLATMA KULESİ | T32: KLNB | V32: YOK | W32: 000000000000000000000000000000 | AB32: 25000 | AG32: GRUP MAKİNELERİ | AH32: KLV A.Ş. | AI32: 4909501006 (KOHLER KDW1003GE) | AK32: TRY | AN32: 0 | AO32: 0 | AP32: KLV A.Ş. | AQ32: 0 | AU32: 18201141
A33: =L33 -> LTW-017 | B33: 1000 | C33: 1001 | D33: 46128 | E33: 2958465 | F33: EQ1553 | G33: 1035 | H33: 135 | I33: 10001035 | J33: 1035-01 | K33: ISIK KULE | L33: LTW-017 | M33: AYDINLATMA KULESİ CHICAGO PNEUMATIC | N33: CPLT V15 MH - 5.4 KW | O33: WUX916188 | P33: CHICAGO PNEUMATIC | Q33: 2018 | R33: T | S33: AYDINLATMA KULESİ | T33: KLNB | V33: YOK | W33: 000000000000000000000000000000 | AB33: 25000 | AG33: GRUP MAKİNELERİ | AH33: KLV A.Ş. | AK33: TRY | AN33: 0 | AO33: 0 | AP33: KLV A.Ş. | AQ33: 0 | AU33: WUX916185
A34: =L34 -> LTW-026 | B34: 1000 | C34: 1001 | D34: 46261 | E34: 2958465 | F34: EQ3927 | G34: 1038 | H34: 138 | I34: 10001038 | J34: 1038-01 | K34: ISIK KULE | L34: LTW-026 | M34: AYDINLATMA KULESİ ITALTOWER FENIX GEN01 | N34: FENIX GEN01 | P34: ITALTOWER | Q34: 2026 | R34: T | S34: AYDINLATMA KULESİ | T34: KLNB | W34: 000000000000000000000000000000 | AB34: 0 | AG34: GRUP MAKİNELERİ | AH34: KLV A.Ş. | AI34: 5326500216 | AN34: 0 | AO34: 0 | AP34: KLV A.Ş. | AQ34: 0 | AU34: 260462
A35: =L35 -> LTW-027 | B35: 1000 | C35: 1001 | D35: 46261 | E35: 2958465 | F35: EQ3928 | G35: 1038 | H35: 138 | I35: 10001038 | J35: 1038-01 | K35: ISIK KULE | L35: LTW-027 | M35: AYDINLATMA KULESİ ITALTOWER FENIX GEN01 | N35: FENIX GEN01 | P35: ITALTOWER | Q35: 2026 | R35: T | S35: AYDINLATMA KULESİ | T35: KLNB | W35: 000000000000000000000000000000 | AB35: 0 | AG35: GRUP MAKİNELERİ | AH35: KLV A.Ş. | AI35: 5329800136 | AN35: 0 | AO35: 0 | AP35: KLV A.Ş. | AQ35: 0 | AU35: 260464
A36: =L36 -> LTW-028 | B36: 1000 | C36: 1001 | D36: 46261 | E36: 2958465 | F36: EQ3929 | G36: 1038 | H36: 138 | I36: 10001038 | J36: 1038-01 | K36: ISIK KULE | L36: LTW-028 | M36: AYDINLATMA KULESİ ITALTOWER FENIX GEN01 | N36: FENIX GEN01 | P36: ITALTOWER | Q36: 2026 | R36: T | S36: AYDINLATMA KULESİ | T36: KLNB | W36: 000000000000000000000000000000 | AB36: 0 | AG36: GRUP MAKİNELERİ | AH36: KLV A.Ş. | AI36: 5326500266 | AN36: 0 | AO36: 0 | AP36: KLV A.Ş. | AQ36: 0 | AU36: 260465
A37: =L37 -> LTW-029 | B37: 1000 | C37: 1001 | D37: 46261 | E37: 2958465 | F37: EQ3930 | G37: 1038 | H37: 138 | I37: 10001038 | J37: 1038-01 | K37: ISIK KULE | L37: LTW-029 | M37: AYDINLATMA KULESİ ITALTOWER FENIX GEN01 | N37: FENIX GEN01 | P37: ITALTOWER | Q37: 2026 | R37: T | S37: AYDINLATMA KULESİ | T37: KLNB | W37: 000000000000000000000000000000 | AB37: 0 | AG37: GRUP MAKİNELERİ | AH37: KLV A.Ş. | AI37: 5329800376 | AN37: 0 | AO37: 0 | AP37: KLV A.Ş. | AQ37: 0 | AU37: 260466
A38: =L38 -> JNR-014 | B38: 1000 | C38: 1001 | D38: 46112 | E38: 2958465 | F38: EQ0655 | G38: 1035 | H38: 135 | I38: 10001035 | J38: 1035-01 | K38: JENERATOR | L38: JNR-014 | M38: JENERATÖR DİESEL AKSA APD33A 35 KWA | N38: APD33A - 35 KVA -DIZ | O38: JNR-014 | P38: AKSA | Q38: 2017 | R38: T | S38: JENERATÖR | T38: KLNB | V38: YOK | W38: 000000000000000000000000000000 | AB38: 0 | AG38: GRUP MAKİNELERİ | AH38: KLV A.Ş. | AI38: 17001080 | AN38: 0 | AO38: 0 | AP38: KLV A.Ş. | AQ38: 0 | AU38: 17001080
A39: =L39 -> JNR-018 | B39: 1000 | C39: 1001 | D39: 46112 | E39: 2958465 | F39: EQ0659 | G39: 1035 | H39: 135 | I39: 10001035 | J39: 1035-01 | K39: JENERATOR | L39: JNR-018 | M39: JENERATÖR FE POWER FE-Y17 | N39: FE-Y17 | O39: JNR-018 | P39: FE POWER | R39: T | S39: JENERATÖR | T39: KLNB | V39: YOK | W39: 000000000000000000000000000000 | AB39: 0 | AG39: GRUP MAKİNELERİ | AH39: KLV A.Ş. | AN39: 0 | AO39: 0 | AP39: KLV A.Ş. | AQ39: 0 | AU39: EXPBK2020-130
A40: =L40 -> JNR-020 | B40: 1000 | C40: 1001 | D40: 46183 | E40: 2958465 | F40: EQ0661 | G40: 1035 | H40: 135 | I40: 10001035 | J40: 1035-01 | K40: JENERATOR | L40: JNR-020 | M40: AKSA TURBOCHARGER - 800 KVA ( KTA2300 G | N40: TURBOCHARGER - 800 K | O40: H10228 | P40: AKSA | R40: T | S40: JENERATÖR | T40: KLNB | V40: YOK | W40: 000000000000000000000000000000 | AB40: 0 | AG40: GRUP MAKİNELERİ | AH40: KLV A.Ş. | AI40: CUMMIS KTA2300G (33101889) | AN40: 0 | AO40: 0 | AP40: KLV A.Ş. | AQ40: 0 | AU40: H10228
...
